<?xml version="1.0" encoding="UTF-8"?>
<testsuite errors="84" failures="0" name="test_segment_size_post_production_tests.ProductionTests-20170628132954" skipped="0" tests="84" time="196.395">
	<testcase classname="test_segment_size_post_production_tests.ProductionTests" name="test_brands_and_categ_and_behaviours_and_country_us_and_state_and_gender_and_age_and_exclude_dma_and_exclude_brand" time="3.771">
		<error message="mysql_connect() takes exactly 2 arguments (1 given)" type="TypeError">
<![CDATA[Traceback (most recent call last):
  File "/Users/sakthigurumaharaj/Desktop/xad/sakthixad/cab_automation/test_segment_size_post_production_tests.py", line 1188, in test_brands_and_categ_and_behaviours_and_country_us_and_state_and_gender_and_age_and_exclude_dma_and_exclude_brand
    verify_data_in_db_helper(count,"76",query)
  File "/Users/sakthigurumaharaj/Desktop/xad/sakthixad/cab_automation/framework/helpers/prod_data_validation_helper.py", line 21, in verify_data_in_db_helper
    cnx = mysql_connect("test_cab")
TypeError: mysql_connect() takes exactly 2 arguments (1 given)
]]>		</error>
	</testcase>
	<testcase classname="test_segment_size_post_production_tests.ProductionTests" name="test_brands_and_categ_and_behaviours_and_country_us_and_state_and_gender_and_multiple_age_and_exclude_dma_and_exclude_brand" time="4.211">
		<error message="mysql_connect() takes exactly 2 arguments (1 given)" type="TypeError">
<![CDATA[Traceback (most recent call last):
  File "/Users/sakthigurumaharaj/Desktop/xad/sakthixad/cab_automation/test_segment_size_post_production_tests.py", line 1314, in test_brands_and_categ_and_behaviours_and_country_us_and_state_and_gender_and_multiple_age_and_exclude_dma_and_exclude_brand
    verify_data_in_db_helper(count,"78",query)
  File "/Users/sakthigurumaharaj/Desktop/xad/sakthixad/cab_automation/framework/helpers/prod_data_validation_helper.py", line 21, in verify_data_in_db_helper
    cnx = mysql_connect("test_cab")
TypeError: mysql_connect() takes exactly 2 arguments (1 given)
]]>		</error>
	</testcase>
	<testcase classname="test_segment_size_post_production_tests.ProductionTests" name="test_brands_and_categ_and_behaviours_and_country_us_and_state_and_gender_and_multiple_age_and_exclude_dma_and_exclude_brand_and_exclude_behavior" time="4.507">
		<error message="mysql_connect() takes exactly 2 arguments (1 given)" type="TypeError">
<![CDATA[Traceback (most recent call last):
  File "/Users/sakthigurumaharaj/Desktop/xad/sakthixad/cab_automation/test_segment_size_post_production_tests.py", line 1377, in test_brands_and_categ_and_behaviours_and_country_us_and_state_and_gender_and_multiple_age_and_exclude_dma_and_exclude_brand_and_exclude_behavior
    verify_data_in_db_helper(count,"79",query)
  File "/Users/sakthigurumaharaj/Desktop/xad/sakthixad/cab_automation/framework/helpers/prod_data_validation_helper.py", line 21, in verify_data_in_db_helper
    cnx = mysql_connect("test_cab")
TypeError: mysql_connect() takes exactly 2 arguments (1 given)
]]>		</error>
	</testcase>
	<testcase classname="test_segment_size_post_production_tests.ProductionTests" name="test_brands_or_categ_or_behaviours_and_country_us" time="2.663">
		<error message="mysql_connect() takes exactly 2 arguments (1 given)" type="TypeError">
<![CDATA[Traceback (most recent call last):
  File "/Users/sakthigurumaharaj/Desktop/xad/sakthixad/cab_automation/test_segment_size_post_production_tests.py", line 1125, in test_brands_or_categ_or_behaviours_and_country_us
    verify_data_in_db_helper(count,"75",query)
  File "/Users/sakthigurumaharaj/Desktop/xad/sakthixad/cab_automation/framework/helpers/prod_data_validation_helper.py", line 21, in verify_data_in_db_helper
    cnx = mysql_connect("test_cab")
TypeError: mysql_connect() takes exactly 2 arguments (1 given)
]]>		</error>
	</testcase>
	<testcase classname="test_segment_size_post_production_tests.ProductionTests" name="test_brands_or_categ_or_behaviours_and_country_us_and_state_and_gender_and_age_and_exclude_dma_and_exclude_brand" time="3.343">
		<error message="mysql_connect() takes exactly 2 arguments (1 given)" type="TypeError">
<![CDATA[Traceback (most recent call last):
  File "/Users/sakthigurumaharaj/Desktop/xad/sakthixad/cab_automation/test_segment_size_post_production_tests.py", line 1252, in test_brands_or_categ_or_behaviours_and_country_us_and_state_and_gender_and_age_and_exclude_dma_and_exclude_brand
    verify_data_in_db_helper(count,"77",query)
  File "/Users/sakthigurumaharaj/Desktop/xad/sakthixad/cab_automation/framework/helpers/prod_data_validation_helper.py", line 21, in verify_data_in_db_helper
    cnx = mysql_connect("test_cab")
TypeError: mysql_connect() takes exactly 2 arguments (1 given)
]]>		</error>
	</testcase>
	<testcase classname="test_segment_size_post_production_tests.ProductionTests" name="test_brands_or_categ_or_behaviours_and_country_us_and_state_and_gender_and_multiple_age_and_exclude_dma_and_exclude_brand_and_exclude_behavior" time="4.442">
		<error message="mysql_connect() takes exactly 2 arguments (1 given)" type="TypeError">
<![CDATA[Traceback (most recent call last):
  File "/Users/sakthigurumaharaj/Desktop/xad/sakthixad/cab_automation/test_segment_size_post_production_tests.py", line 1440, in test_brands_or_categ_or_behaviours_and_country_us_and_state_and_gender_and_multiple_age_and_exclude_dma_and_exclude_brand_and_exclude_behavior
    verify_data_in_db_helper(count,"80",query)
  File "/Users/sakthigurumaharaj/Desktop/xad/sakthixad/cab_automation/framework/helpers/prod_data_validation_helper.py", line 21, in verify_data_in_db_helper
    cnx = mysql_connect("test_cab")
TypeError: mysql_connect() takes exactly 2 arguments (1 given)
]]>		</error>
	</testcase>
	<testcase classname="test_segment_size_post_production_tests.ProductionTests" name="test_brands_or_categ_or_behaviours_and_country_us_and_state_and_gender_and_multiple_age_and_exclude_dma_and_exclude_brand_and_exclude_behavior_include_and_exclude_segment" time="4.948">
		<error message="mysql_connect() takes exactly 2 arguments (1 given)" type="TypeError">
<![CDATA[Traceback (most recent call last):
  File "/Users/sakthigurumaharaj/Desktop/xad/sakthixad/cab_automation/test_segment_size_post_production_tests.py", line 1528, in test_brands_or_categ_or_behaviours_and_country_us_and_state_and_gender_and_multiple_age_and_exclude_dma_and_exclude_brand_and_exclude_behavior_include_and_exclude_segment
    verify_data_in_db_helper(count,"82",query)
  File "/Users/sakthigurumaharaj/Desktop/xad/sakthixad/cab_automation/framework/helpers/prod_data_validation_helper.py", line 21, in verify_data_in_db_helper
    cnx = mysql_connect("test_cab")
TypeError: mysql_connect() takes exactly 2 arguments (1 given)
]]>		</error>
	</testcase>
	<testcase classname="test_segment_size_post_production_tests.ProductionTests" name="test_country_and_or_between_states_and_dmas" time="3.035">
		<error message="mysql_connect() takes exactly 2 arguments (1 given)" type="TypeError">
<![CDATA[Traceback (most recent call last):
  File "/Users/sakthigurumaharaj/Desktop/xad/sakthixad/cab_automation/test_segment_size_post_production_tests.py", line 1058, in test_country_and_or_between_states_and_dmas
    verify_data_in_db_helper(count,"73",query)
  File "/Users/sakthigurumaharaj/Desktop/xad/sakthixad/cab_automation/framework/helpers/prod_data_validation_helper.py", line 21, in verify_data_in_db_helper
    cnx = mysql_connect("test_cab")
TypeError: mysql_connect() takes exactly 2 arguments (1 given)
]]>		</error>
	</testcase>
	<testcase classname="test_segment_size_post_production_tests.ProductionTests" name="test_country_and_or_between_states_and_dmas_and_not_dma" time="3.278">
		<error message="mysql_connect() takes exactly 2 arguments (1 given)" type="TypeError">
<![CDATA[Traceback (most recent call last):
  File "/Users/sakthigurumaharaj/Desktop/xad/sakthixad/cab_automation/test_segment_size_post_production_tests.py", line 1086, in test_country_and_or_between_states_and_dmas_and_not_dma
    verify_data_in_db_helper(count,"74",query)
  File "/Users/sakthigurumaharaj/Desktop/xad/sakthixad/cab_automation/framework/helpers/prod_data_validation_helper.py", line 21, in verify_data_in_db_helper
    cnx = mysql_connect("test_cab")
TypeError: mysql_connect() takes exactly 2 arguments (1 given)
]]>		</error>
	</testcase>
	<testcase classname="test_segment_size_post_production_tests.ProductionTests" name="test_country_and_or_between_states_and_exlude_multiple_dmas" time="2.662">
		<error message="mysql_connect() takes exactly 2 arguments (1 given)" type="TypeError">
<![CDATA[Traceback (most recent call last):
  File "/Users/sakthigurumaharaj/Desktop/xad/sakthixad/cab_automation/test_segment_size_post_production_tests.py", line 1031, in test_country_and_or_between_states_and_exlude_multiple_dmas
    verify_data_in_db_helper(count,"72",query)
  File "/Users/sakthigurumaharaj/Desktop/xad/sakthixad/cab_automation/framework/helpers/prod_data_validation_helper.py", line 21, in verify_data_in_db_helper
    cnx = mysql_connect("test_cab")
TypeError: mysql_connect() takes exactly 2 arguments (1 given)
]]>		</error>
	</testcase>
	<testcase classname="test_segment_size_post_production_tests.ProductionTests" name="test_users_in_cn_and_are_soccermoms" time="2.405">
		<error message="mysql_connect() takes exactly 2 arguments (1 given)" type="TypeError">
<![CDATA[Traceback (most recent call last):
  File "/Users/sakthigurumaharaj/Desktop/xad/sakthixad/cab_automation/test_segment_size_post_production_tests.py", line 768, in test_users_in_cn_and_are_soccermoms
    verify_data_in_db_helper(count,"56",query)
  File "/Users/sakthigurumaharaj/Desktop/xad/sakthixad/cab_automation/framework/helpers/prod_data_validation_helper.py", line 21, in verify_data_in_db_helper
    cnx = mysql_connect("test_cab")
TypeError: mysql_connect() takes exactly 2 arguments (1 given)
]]>		</error>
	</testcase>
	<testcase classname="test_segment_size_post_production_tests.ProductionTests" name="test_users_in_gb" time="1.689">
		<error message="mysql_connect() takes exactly 2 arguments (1 given)" type="TypeError">
<![CDATA[Traceback (most recent call last):
  File "/Users/sakthigurumaharaj/Desktop/xad/sakthixad/cab_automation/test_segment_size_post_production_tests.py", line 36, in test_users_in_gb
    verify_data_in_db_helper(count,"2",query)
  File "/Users/sakthigurumaharaj/Desktop/xad/sakthixad/cab_automation/framework/helpers/prod_data_validation_helper.py", line 21, in verify_data_in_db_helper
    cnx = mysql_connect("test_cab")
TypeError: mysql_connect() takes exactly 2 arguments (1 given)
]]>		</error>
	</testcase>
	<testcase classname="test_segment_size_post_production_tests.ProductionTests" name="test_users_in_gb_and_age_13_to_17" time="1.435">
		<error message="mysql_connect() takes exactly 2 arguments (1 given)" type="TypeError">
<![CDATA[Traceback (most recent call last):
  File "/Users/sakthigurumaharaj/Desktop/xad/sakthixad/cab_automation/test_segment_size_post_production_tests.py", line 242, in test_users_in_gb_and_age_13_to_17
    verify_data_in_db_helper(count,"17",query)
  File "/Users/sakthigurumaharaj/Desktop/xad/sakthixad/cab_automation/framework/helpers/prod_data_validation_helper.py", line 21, in verify_data_in_db_helper
    cnx = mysql_connect("test_cab")
TypeError: mysql_connect() takes exactly 2 arguments (1 given)
]]>		</error>
	</testcase>
	<testcase classname="test_segment_size_post_production_tests.ProductionTests" name="test_users_in_gb_and_age_18_to_24" time="1.432">
		<error message="mysql_connect() takes exactly 2 arguments (1 given)" type="TypeError">
<![CDATA[Traceback (most recent call last):
  File "/Users/sakthigurumaharaj/Desktop/xad/sakthixad/cab_automation/test_segment_size_post_production_tests.py", line 256, in test_users_in_gb_and_age_18_to_24
    verify_data_in_db_helper(count,"18",query)
  File "/Users/sakthigurumaharaj/Desktop/xad/sakthixad/cab_automation/framework/helpers/prod_data_validation_helper.py", line 21, in verify_data_in_db_helper
    cnx = mysql_connect("test_cab")
TypeError: mysql_connect() takes exactly 2 arguments (1 given)
]]>		</error>
	</testcase>
	<testcase classname="test_segment_size_post_production_tests.ProductionTests" name="test_users_in_gb_and_age_25_to_34" time="2.530">
		<error message="mysql_connect() takes exactly 2 arguments (1 given)" type="TypeError">
<![CDATA[Traceback (most recent call last):
  File "/Users/sakthigurumaharaj/Desktop/xad/sakthixad/cab_automation/test_segment_size_post_production_tests.py", line 270, in test_users_in_gb_and_age_25_to_34
    verify_data_in_db_helper(count,"19",query)
  File "/Users/sakthigurumaharaj/Desktop/xad/sakthixad/cab_automation/framework/helpers/prod_data_validation_helper.py", line 21, in verify_data_in_db_helper
    cnx = mysql_connect("test_cab")
TypeError: mysql_connect() takes exactly 2 arguments (1 given)
]]>		</error>
	</testcase>
	<testcase classname="test_segment_size_post_production_tests.ProductionTests" name="test_users_in_gb_and_age_35_to_44" time="2.385">
		<error message="mysql_connect() takes exactly 2 arguments (1 given)" type="TypeError">
<![CDATA[Traceback (most recent call last):
  File "/Users/sakthigurumaharaj/Desktop/xad/sakthixad/cab_automation/test_segment_size_post_production_tests.py", line 284, in test_users_in_gb_and_age_35_to_44
    verify_data_in_db_helper(count,"20",query)
  File "/Users/sakthigurumaharaj/Desktop/xad/sakthixad/cab_automation/framework/helpers/prod_data_validation_helper.py", line 21, in verify_data_in_db_helper
    cnx = mysql_connect("test_cab")
TypeError: mysql_connect() takes exactly 2 arguments (1 given)
]]>		</error>
	</testcase>
	<testcase classname="test_segment_size_post_production_tests.ProductionTests" name="test_users_in_gb_and_age_45_to_54" time="2.460">
		<error message="mysql_connect() takes exactly 2 arguments (1 given)" type="TypeError">
<![CDATA[Traceback (most recent call last):
  File "/Users/sakthigurumaharaj/Desktop/xad/sakthixad/cab_automation/test_segment_size_post_production_tests.py", line 298, in test_users_in_gb_and_age_45_to_54
    verify_data_in_db_helper(count,"21",query)
  File "/Users/sakthigurumaharaj/Desktop/xad/sakthixad/cab_automation/framework/helpers/prod_data_validation_helper.py", line 21, in verify_data_in_db_helper
    cnx = mysql_connect("test_cab")
TypeError: mysql_connect() takes exactly 2 arguments (1 given)
]]>		</error>
	</testcase>
	<testcase classname="test_segment_size_post_production_tests.ProductionTests" name="test_users_in_gb_and_age_55_to_64" time="1.945">
		<error message="mysql_connect() takes exactly 2 arguments (1 given)" type="TypeError">
<![CDATA[Traceback (most recent call last):
  File "/Users/sakthigurumaharaj/Desktop/xad/sakthixad/cab_automation/test_segment_size_post_production_tests.py", line 312, in test_users_in_gb_and_age_55_to_64
    verify_data_in_db_helper(count,"22",query)
  File "/Users/sakthigurumaharaj/Desktop/xad/sakthixad/cab_automation/framework/helpers/prod_data_validation_helper.py", line 21, in verify_data_in_db_helper
    cnx = mysql_connect("test_cab")
TypeError: mysql_connect() takes exactly 2 arguments (1 given)
]]>		</error>
	</testcase>
	<testcase classname="test_segment_size_post_production_tests.ProductionTests" name="test_users_in_gb_and_age_greater_than_65" time="2.470">
		<error message="mysql_connect() takes exactly 2 arguments (1 given)" type="TypeError">
<![CDATA[Traceback (most recent call last):
  File "/Users/sakthigurumaharaj/Desktop/xad/sakthixad/cab_automation/test_segment_size_post_production_tests.py", line 326, in test_users_in_gb_and_age_greater_than_65
    verify_data_in_db_helper(count,"23",query)
  File "/Users/sakthigurumaharaj/Desktop/xad/sakthixad/cab_automation/framework/helpers/prod_data_validation_helper.py", line 21, in verify_data_in_db_helper
    cnx = mysql_connect("test_cab")
TypeError: mysql_connect() takes exactly 2 arguments (1 given)
]]>		</error>
	</testcase>
	<testcase classname="test_segment_size_post_production_tests.ProductionTests" name="test_users_in_gb_and_age_unknown" time="1.979">
		<error message="mysql_connect() takes exactly 2 arguments (1 given)" type="TypeError">
<![CDATA[Traceback (most recent call last):
  File "/Users/sakthigurumaharaj/Desktop/xad/sakthixad/cab_automation/test_segment_size_post_production_tests.py", line 340, in test_users_in_gb_and_age_unknown
    verify_data_in_db_helper(count,"24",query)
  File "/Users/sakthigurumaharaj/Desktop/xad/sakthixad/cab_automation/framework/helpers/prod_data_validation_helper.py", line 21, in verify_data_in_db_helper
    cnx = mysql_connect("test_cab")
TypeError: mysql_connect() takes exactly 2 arguments (1 given)
]]>		</error>
	</testcase>
	<testcase classname="test_segment_size_post_production_tests.ProductionTests" name="test_users_in_uk_and_female" time="2.412">
		<error message="mysql_connect() takes exactly 2 arguments (1 given)" type="TypeError">
<![CDATA[Traceback (most recent call last):
  File "/Users/sakthigurumaharaj/Desktop/xad/sakthixad/cab_automation/test_segment_size_post_production_tests.py", line 103, in test_users_in_uk_and_female
    verify_data_in_db_helper(count,"7",query)
  File "/Users/sakthigurumaharaj/Desktop/xad/sakthixad/cab_automation/framework/helpers/prod_data_validation_helper.py", line 21, in verify_data_in_db_helper
    cnx = mysql_connect("test_cab")
TypeError: mysql_connect() takes exactly 2 arguments (1 given)
]]>		</error>
	</testcase>
	<testcase classname="test_segment_size_post_production_tests.ProductionTests" name="test_users_in_uk_and_male" time="2.251">
		<error message="mysql_connect() takes exactly 2 arguments (1 given)" type="TypeError">
<![CDATA[Traceback (most recent call last):
  File "/Users/sakthigurumaharaj/Desktop/xad/sakthixad/cab_automation/test_segment_size_post_production_tests.py", line 90, in test_users_in_uk_and_male
    verify_data_in_db_helper(count,"6",query)
  File "/Users/sakthigurumaharaj/Desktop/xad/sakthixad/cab_automation/framework/helpers/prod_data_validation_helper.py", line 21, in verify_data_in_db_helper
    cnx = mysql_connect("test_cab")
TypeError: mysql_connect() takes exactly 2 arguments (1 given)
]]>		</error>
	</testcase>
	<testcase classname="test_segment_size_post_production_tests.ProductionTests" name="test_users_in_uk_and_unknown" time="2.459">
		<error message="mysql_connect() takes exactly 2 arguments (1 given)" type="TypeError">
<![CDATA[Traceback (most recent call last):
  File "/Users/sakthigurumaharaj/Desktop/xad/sakthixad/cab_automation/test_segment_size_post_production_tests.py", line 116, in test_users_in_uk_and_unknown
    verify_data_in_db_helper(count,"8",query)
  File "/Users/sakthigurumaharaj/Desktop/xad/sakthixad/cab_automation/framework/helpers/prod_data_validation_helper.py", line 21, in verify_data_in_db_helper
    cnx = mysql_connect("test_cab")
TypeError: mysql_connect() takes exactly 2 arguments (1 given)
]]>		</error>
	</testcase>
	<testcase classname="test_segment_size_post_production_tests.ProductionTests" name="test_users_in_us" time="1.639">
		<error message="mysql_connect() takes exactly 2 arguments (1 given)" type="TypeError">
<![CDATA[Traceback (most recent call last):
  File "/Users/sakthigurumaharaj/Desktop/xad/sakthixad/cab_automation/test_segment_size_post_production_tests.py", line 25, in test_users_in_us
    verify_data_in_db_helper(count,"1",query)
  File "/Users/sakthigurumaharaj/Desktop/xad/sakthixad/cab_automation/framework/helpers/prod_data_validation_helper.py", line 21, in verify_data_in_db_helper
    cnx = mysql_connect("test_cab")
TypeError: mysql_connect() takes exactly 2 arguments (1 given)
]]>		</error>
	</testcase>
	<testcase classname="test_segment_size_post_production_tests.ProductionTests" name="test_users_in_us_and_age_13_to_17" time="2.263">
		<error message="mysql_connect() takes exactly 2 arguments (1 given)" type="TypeError">
<![CDATA[Traceback (most recent call last):
  File "/Users/sakthigurumaharaj/Desktop/xad/sakthixad/cab_automation/test_segment_size_post_production_tests.py", line 130, in test_users_in_us_and_age_13_to_17
    verify_data_in_db_helper(count,"9",query)
  File "/Users/sakthigurumaharaj/Desktop/xad/sakthixad/cab_automation/framework/helpers/prod_data_validation_helper.py", line 21, in verify_data_in_db_helper
    cnx = mysql_connect("test_cab")
TypeError: mysql_connect() takes exactly 2 arguments (1 given)
]]>		</error>
	</testcase>
	<testcase classname="test_segment_size_post_production_tests.ProductionTests" name="test_users_in_us_and_age_18_to_24" time="2.346">
		<error message="mysql_connect() takes exactly 2 arguments (1 given)" type="TypeError">
<![CDATA[Traceback (most recent call last):
  File "/Users/sakthigurumaharaj/Desktop/xad/sakthixad/cab_automation/test_segment_size_post_production_tests.py", line 144, in test_users_in_us_and_age_18_to_24
    verify_data_in_db_helper(count,"10",query)
  File "/Users/sakthigurumaharaj/Desktop/xad/sakthixad/cab_automation/framework/helpers/prod_data_validation_helper.py", line 21, in verify_data_in_db_helper
    cnx = mysql_connect("test_cab")
TypeError: mysql_connect() takes exactly 2 arguments (1 given)
]]>		</error>
	</testcase>
	<testcase classname="test_segment_size_post_production_tests.ProductionTests" name="test_users_in_us_and_age_25_to_34" time="2.352">
		<error message="mysql_connect() takes exactly 2 arguments (1 given)" type="TypeError">
<![CDATA[Traceback (most recent call last):
  File "/Users/sakthigurumaharaj/Desktop/xad/sakthixad/cab_automation/test_segment_size_post_production_tests.py", line 158, in test_users_in_us_and_age_25_to_34
    verify_data_in_db_helper(count,"11",query)
  File "/Users/sakthigurumaharaj/Desktop/xad/sakthixad/cab_automation/framework/helpers/prod_data_validation_helper.py", line 21, in verify_data_in_db_helper
    cnx = mysql_connect("test_cab")
TypeError: mysql_connect() takes exactly 2 arguments (1 given)
]]>		</error>
	</testcase>
	<testcase classname="test_segment_size_post_production_tests.ProductionTests" name="test_users_in_us_and_age_35_to_44" time="1.537">
		<error message="mysql_connect() takes exactly 2 arguments (1 given)" type="TypeError">
<![CDATA[Traceback (most recent call last):
  File "/Users/sakthigurumaharaj/Desktop/xad/sakthixad/cab_automation/test_segment_size_post_production_tests.py", line 172, in test_users_in_us_and_age_35_to_44
    verify_data_in_db_helper(count,"12",query)
  File "/Users/sakthigurumaharaj/Desktop/xad/sakthixad/cab_automation/framework/helpers/prod_data_validation_helper.py", line 21, in verify_data_in_db_helper
    cnx = mysql_connect("test_cab")
TypeError: mysql_connect() takes exactly 2 arguments (1 given)
]]>		</error>
	</testcase>
	<testcase classname="test_segment_size_post_production_tests.ProductionTests" name="test_users_in_us_and_age_45_to_54" time="2.250">
		<error message="mysql_connect() takes exactly 2 arguments (1 given)" type="TypeError">
<![CDATA[Traceback (most recent call last):
  File "/Users/sakthigurumaharaj/Desktop/xad/sakthixad/cab_automation/test_segment_size_post_production_tests.py", line 186, in test_users_in_us_and_age_45_to_54
    verify_data_in_db_helper(count,"13",query)
  File "/Users/sakthigurumaharaj/Desktop/xad/sakthixad/cab_automation/framework/helpers/prod_data_validation_helper.py", line 21, in verify_data_in_db_helper
    cnx = mysql_connect("test_cab")
TypeError: mysql_connect() takes exactly 2 arguments (1 given)
]]>		</error>
	</testcase>
	<testcase classname="test_segment_size_post_production_tests.ProductionTests" name="test_users_in_us_and_age_55_to_64" time="2.020">
		<error message="mysql_connect() takes exactly 2 arguments (1 given)" type="TypeError">
<![CDATA[Traceback (most recent call last):
  File "/Users/sakthigurumaharaj/Desktop/xad/sakthixad/cab_automation/test_segment_size_post_production_tests.py", line 200, in test_users_in_us_and_age_55_to_64
    verify_data_in_db_helper(count,"14",query)
  File "/Users/sakthigurumaharaj/Desktop/xad/sakthixad/cab_automation/framework/helpers/prod_data_validation_helper.py", line 21, in verify_data_in_db_helper
    cnx = mysql_connect("test_cab")
TypeError: mysql_connect() takes exactly 2 arguments (1 given)
]]>		</error>
	</testcase>
	<testcase classname="test_segment_size_post_production_tests.ProductionTests" name="test_users_in_us_and_age_greater_than_65" time="2.181">
		<error message="mysql_connect() takes exactly 2 arguments (1 given)" type="TypeError">
<![CDATA[Traceback (most recent call last):
  File "/Users/sakthigurumaharaj/Desktop/xad/sakthixad/cab_automation/test_segment_size_post_production_tests.py", line 214, in test_users_in_us_and_age_greater_than_65
    verify_data_in_db_helper(count,"15",query)
  File "/Users/sakthigurumaharaj/Desktop/xad/sakthixad/cab_automation/framework/helpers/prod_data_validation_helper.py", line 21, in verify_data_in_db_helper
    cnx = mysql_connect("test_cab")
TypeError: mysql_connect() takes exactly 2 arguments (1 given)
]]>		</error>
	</testcase>
	<testcase classname="test_segment_size_post_production_tests.ProductionTests" name="test_users_in_us_and_big_city_moms" time="2.256">
		<error message="mysql_connect() takes exactly 2 arguments (1 given)" type="TypeError">
<![CDATA[Traceback (most recent call last):
  File "/Users/sakthigurumaharaj/Desktop/xad/sakthixad/cab_automation/test_segment_size_post_production_tests.py", line 742, in test_users_in_us_and_big_city_moms
    verify_data_in_db_helper(count,"54",query)
  File "/Users/sakthigurumaharaj/Desktop/xad/sakthixad/cab_automation/framework/helpers/prod_data_validation_helper.py", line 21, in verify_data_in_db_helper
    cnx = mysql_connect("test_cab")
TypeError: mysql_connect() takes exactly 2 arguments (1 given)
]]>		</error>
	</testcase>
	<testcase classname="test_segment_size_post_production_tests.ProductionTests" name="test_users_in_us_and_commuters" time="1.327">
		<error message="mysql_connect() takes exactly 2 arguments (1 given)" type="TypeError">
<![CDATA[Traceback (most recent call last):
  File "/Users/sakthigurumaharaj/Desktop/xad/sakthixad/cab_automation/test_segment_size_post_production_tests.py", line 677, in test_users_in_us_and_commuters
    verify_data_in_db_helper(count,"49",query)
  File "/Users/sakthigurumaharaj/Desktop/xad/sakthixad/cab_automation/framework/helpers/prod_data_validation_helper.py", line 21, in verify_data_in_db_helper
    cnx = mysql_connect("test_cab")
TypeError: mysql_connect() takes exactly 2 arguments (1 given)
]]>		</error>
	</testcase>
	<testcase classname="test_segment_size_post_production_tests.ProductionTests" name="test_users_in_us_and_dad" time="2.255">
		<error message="mysql_connect() takes exactly 2 arguments (1 given)" type="TypeError">
<![CDATA[Traceback (most recent call last):
  File "/Users/sakthigurumaharaj/Desktop/xad/sakthixad/cab_automation/test_segment_size_post_production_tests.py", line 716, in test_users_in_us_and_dad
    verify_data_in_db_helper(count,"52",query)
  File "/Users/sakthigurumaharaj/Desktop/xad/sakthixad/cab_automation/framework/helpers/prod_data_validation_helper.py", line 21, in verify_data_in_db_helper
    cnx = mysql_connect("test_cab")
TypeError: mysql_connect() takes exactly 2 arguments (1 given)
]]>		</error>
	</testcase>
	<testcase classname="test_segment_size_post_production_tests.ProductionTests" name="test_users_in_us_and_diys" time="2.533">
		<error message="mysql_connect() takes exactly 2 arguments (1 given)" type="TypeError">
<![CDATA[Traceback (most recent call last):
  File "/Users/sakthigurumaharaj/Desktop/xad/sakthixad/cab_automation/test_segment_size_post_production_tests.py", line 690, in test_users_in_us_and_diys
    verify_data_in_db_helper(count,"50",query)
  File "/Users/sakthigurumaharaj/Desktop/xad/sakthixad/cab_automation/framework/helpers/prod_data_validation_helper.py", line 21, in verify_data_in_db_helper
    cnx = mysql_connect("test_cab")
TypeError: mysql_connect() takes exactly 2 arguments (1 given)
]]>		</error>
	</testcase>
	<testcase classname="test_segment_size_post_production_tests.ProductionTests" name="test_users_in_us_and_female" time="2.485">
		<error message="mysql_connect() takes exactly 2 arguments (1 given)" type="TypeError">
<![CDATA[Traceback (most recent call last):
  File "/Users/sakthigurumaharaj/Desktop/xad/sakthixad/cab_automation/test_segment_size_post_production_tests.py", line 64, in test_users_in_us_and_female
    verify_data_in_db_helper(count,"4",query)
  File "/Users/sakthigurumaharaj/Desktop/xad/sakthixad/cab_automation/framework/helpers/prod_data_validation_helper.py", line 21, in verify_data_in_db_helper
    cnx = mysql_connect("test_cab")
TypeError: mysql_connect() takes exactly 2 arguments (1 given)
]]>		</error>
	</testcase>
	<testcase classname="test_segment_size_post_production_tests.ProductionTests" name="test_users_in_us_and_golfers" time="1.126">
		<error message="mysql_connect() takes exactly 2 arguments (1 given)" type="TypeError">
<![CDATA[Traceback (most recent call last):
  File "/Users/sakthigurumaharaj/Desktop/xad/sakthixad/cab_automation/test_segment_size_post_production_tests.py", line 703, in test_users_in_us_and_golfers
    verify_data_in_db_helper(count,"51",query)
  File "/Users/sakthigurumaharaj/Desktop/xad/sakthixad/cab_automation/framework/helpers/prod_data_validation_helper.py", line 21, in verify_data_in_db_helper
    cnx = mysql_connect("test_cab")
TypeError: mysql_connect() takes exactly 2 arguments (1 given)
]]>		</error>
	</testcase>
	<testcase classname="test_segment_size_post_production_tests.ProductionTests" name="test_users_in_us_and_hispanics" time="1.401">
		<error message="mysql_connect() takes exactly 2 arguments (1 given)" type="TypeError">
<![CDATA[Traceback (most recent call last):
  File "/Users/sakthigurumaharaj/Desktop/xad/sakthixad/cab_automation/test_segment_size_post_production_tests.py", line 651, in test_users_in_us_and_hispanics
    verify_data_in_db_helper(count,"47",query)
  File "/Users/sakthigurumaharaj/Desktop/xad/sakthixad/cab_automation/framework/helpers/prod_data_validation_helper.py", line 21, in verify_data_in_db_helper
    cnx = mysql_connect("test_cab")
TypeError: mysql_connect() takes exactly 2 arguments (1 given)
]]>		</error>
	</testcase>
	<testcase classname="test_segment_size_post_production_tests.ProductionTests" name="test_users_in_us_and_home_contractors" time="1.767">
		<error message="mysql_connect() takes exactly 2 arguments (1 given)" type="TypeError">
<![CDATA[Traceback (most recent call last):
  File "/Users/sakthigurumaharaj/Desktop/xad/sakthixad/cab_automation/test_segment_size_post_production_tests.py", line 612, in test_users_in_us_and_home_contractors
    verify_data_in_db_helper(count,"44",query)
  File "/Users/sakthigurumaharaj/Desktop/xad/sakthixad/cab_automation/framework/helpers/prod_data_validation_helper.py", line 21, in verify_data_in_db_helper
    cnx = mysql_connect("test_cab")
TypeError: mysql_connect() takes exactly 2 arguments (1 given)
]]>		</error>
	</testcase>
	<testcase classname="test_segment_size_post_production_tests.ProductionTests" name="test_users_in_us_and_in_california" time="2.360">
		<error message="mysql_connect() takes exactly 2 arguments (1 given)" type="TypeError">
<![CDATA[Traceback (most recent call last):
  File "/Users/sakthigurumaharaj/Desktop/xad/sakthixad/cab_automation/test_segment_size_post_production_tests.py", line 527, in test_users_in_us_and_in_california
    verify_data_in_db_helper(count,"38",query)
  File "/Users/sakthigurumaharaj/Desktop/xad/sakthixad/cab_automation/framework/helpers/prod_data_validation_helper.py", line 21, in verify_data_in_db_helper
    cnx = mysql_connect("test_cab")
TypeError: mysql_connect() takes exactly 2 arguments (1 given)
]]>		</error>
	</testcase>
	<testcase classname="test_segment_size_post_production_tests.ProductionTests" name="test_users_in_us_and_in_california_and_exclude_dma_los_angeles" time="2.562">
		<error message="mysql_connect() takes exactly 2 arguments (1 given)" type="TypeError">
<![CDATA[Traceback (most recent call last):
  File "/Users/sakthigurumaharaj/Desktop/xad/sakthixad/cab_automation/test_segment_size_post_production_tests.py", line 569, in test_users_in_us_and_in_california_and_exclude_dma_los_angeles
    verify_data_in_db_helper(count,"41",query)
  File "/Users/sakthigurumaharaj/Desktop/xad/sakthixad/cab_automation/framework/helpers/prod_data_validation_helper.py", line 21, in verify_data_in_db_helper
    cnx = mysql_connect("test_cab")
TypeError: mysql_connect() takes exactly 2 arguments (1 given)
]]>		</error>
	</testcase>
	<testcase classname="test_segment_size_post_production_tests.ProductionTests" name="test_users_in_us_and_in_california_and_exclude_dma_san_francisco" time="1.636">
		<error message="mysql_connect() takes exactly 2 arguments (1 given)" type="TypeError">
<![CDATA[Traceback (most recent call last):
  File "/Users/sakthigurumaharaj/Desktop/xad/sakthixad/cab_automation/test_segment_size_post_production_tests.py", line 583, in test_users_in_us_and_in_california_and_exclude_dma_san_francisco
    verify_data_in_db_helper(count,"42",query)
  File "/Users/sakthigurumaharaj/Desktop/xad/sakthixad/cab_automation/framework/helpers/prod_data_validation_helper.py", line 21, in verify_data_in_db_helper
    cnx = mysql_connect("test_cab")
TypeError: mysql_connect() takes exactly 2 arguments (1 given)
]]>		</error>
	</testcase>
	<testcase classname="test_segment_size_post_production_tests.ProductionTests" name="test_users_in_us_and_in_market_for_furnitures" time="2.255">
		<error message="mysql_connect() takes exactly 2 arguments (1 given)" type="TypeError">
<![CDATA[Traceback (most recent call last):
  File "/Users/sakthigurumaharaj/Desktop/xad/sakthixad/cab_automation/test_segment_size_post_production_tests.py", line 755, in test_users_in_us_and_in_market_for_furnitures
    verify_data_in_db_helper(count,"55",query)
  File "/Users/sakthigurumaharaj/Desktop/xad/sakthixad/cab_automation/framework/helpers/prod_data_validation_helper.py", line 21, in verify_data_in_db_helper
    cnx = mysql_connect("test_cab")
TypeError: mysql_connect() takes exactly 2 arguments (1 given)
]]>		</error>
	</testcase>
	<testcase classname="test_segment_size_post_production_tests.ProductionTests" name="test_users_in_us_and_in_new_york" time="2.489">
		<error message="mysql_connect() takes exactly 2 arguments (1 given)" type="TypeError">
<![CDATA[Traceback (most recent call last):
  File "/Users/sakthigurumaharaj/Desktop/xad/sakthixad/cab_automation/test_segment_size_post_production_tests.py", line 540, in test_users_in_us_and_in_new_york
    verify_data_in_db_helper(count,"39",query)
  File "/Users/sakthigurumaharaj/Desktop/xad/sakthixad/cab_automation/framework/helpers/prod_data_validation_helper.py", line 21, in verify_data_in_db_helper
    cnx = mysql_connect("test_cab")
TypeError: mysql_connect() takes exactly 2 arguments (1 given)
]]>		</error>
	</testcase>
	<testcase classname="test_segment_size_post_production_tests.ProductionTests" name="test_users_in_us_and_in_new_york_and_exclude_dma_new_york" time="1.812">
		<error message="mysql_connect() takes exactly 2 arguments (1 given)" type="TypeError">
<![CDATA[Traceback (most recent call last):
  File "/Users/sakthigurumaharaj/Desktop/xad/sakthixad/cab_automation/test_segment_size_post_production_tests.py", line 597, in test_users_in_us_and_in_new_york_and_exclude_dma_new_york
    verify_data_in_db_helper(count,"43",query)
  File "/Users/sakthigurumaharaj/Desktop/xad/sakthixad/cab_automation/framework/helpers/prod_data_validation_helper.py", line 21, in verify_data_in_db_helper
    cnx = mysql_connect("test_cab")
TypeError: mysql_connect() takes exactly 2 arguments (1 given)
]]>		</error>
	</testcase>
	<testcase classname="test_segment_size_post_production_tests.ProductionTests" name="test_users_in_us_and_in_texas" time="2.425">
		<error message="mysql_connect() takes exactly 2 arguments (1 given)" type="TypeError">
<![CDATA[Traceback (most recent call last):
  File "/Users/sakthigurumaharaj/Desktop/xad/sakthixad/cab_automation/test_segment_size_post_production_tests.py", line 553, in test_users_in_us_and_in_texas
    verify_data_in_db_helper(count,"40",query)
  File "/Users/sakthigurumaharaj/Desktop/xad/sakthixad/cab_automation/framework/helpers/prod_data_validation_helper.py", line 21, in verify_data_in_db_helper
    cnx = mysql_connect("test_cab")
TypeError: mysql_connect() takes exactly 2 arguments (1 given)
]]>		</error>
	</testcase>
	<testcase classname="test_segment_size_post_production_tests.ProductionTests" name="test_users_in_us_and_inmarket_for_carriers" time="2.289">
		<error message="mysql_connect() takes exactly 2 arguments (1 given)" type="TypeError">
<![CDATA[Traceback (most recent call last):
  File "/Users/sakthigurumaharaj/Desktop/xad/sakthixad/cab_automation/test_segment_size_post_production_tests.py", line 729, in test_users_in_us_and_inmarket_for_carriers
    verify_data_in_db_helper(count,"53",query)
  File "/Users/sakthigurumaharaj/Desktop/xad/sakthixad/cab_automation/framework/helpers/prod_data_validation_helper.py", line 21, in verify_data_in_db_helper
    cnx = mysql_connect("test_cab")
TypeError: mysql_connect() takes exactly 2 arguments (1 given)
]]>		</error>
	</testcase>
	<testcase classname="test_segment_size_post_production_tests.ProductionTests" name="test_users_in_us_and_male" time="1.668">
		<error message="mysql_connect() takes exactly 2 arguments (1 given)" type="TypeError">
<![CDATA[Traceback (most recent call last):
  File "/Users/sakthigurumaharaj/Desktop/xad/sakthixad/cab_automation/test_segment_size_post_production_tests.py", line 51, in test_users_in_us_and_male
    verify_data_in_db_helper(count,"3",query)
  File "/Users/sakthigurumaharaj/Desktop/xad/sakthixad/cab_automation/framework/helpers/prod_data_validation_helper.py", line 21, in verify_data_in_db_helper
    cnx = mysql_connect("test_cab")
TypeError: mysql_connect() takes exactly 2 arguments (1 given)
]]>		</error>
	</testcase>
	<testcase classname="test_segment_size_post_production_tests.ProductionTests" name="test_users_in_us_and_millennials" time="2.418">
		<error message="mysql_connect() takes exactly 2 arguments (1 given)" type="TypeError">
<![CDATA[Traceback (most recent call last):
  File "/Users/sakthigurumaharaj/Desktop/xad/sakthixad/cab_automation/test_segment_size_post_production_tests.py", line 625, in test_users_in_us_and_millennials
    verify_data_in_db_helper(count,"45",query)
  File "/Users/sakthigurumaharaj/Desktop/xad/sakthixad/cab_automation/framework/helpers/prod_data_validation_helper.py", line 21, in verify_data_in_db_helper
    cnx = mysql_connect("test_cab")
TypeError: mysql_connect() takes exactly 2 arguments (1 given)
]]>		</error>
	</testcase>
	<testcase classname="test_segment_size_post_production_tests.ProductionTests" name="test_users_in_us_and_or_not_and_between_segments" time="2.466">
		<error message="mysql_connect() takes exactly 2 arguments (1 given)" type="TypeError">
<![CDATA[Traceback (most recent call last):
  File "/Users/sakthigurumaharaj/Desktop/xad/sakthixad/cab_automation/test_segment_size_post_production_tests.py", line 1457, in test_users_in_us_and_or_not_and_between_segments
    verify_data_in_db_helper(count,"81",query)
  File "/Users/sakthigurumaharaj/Desktop/xad/sakthixad/cab_automation/framework/helpers/prod_data_validation_helper.py", line 21, in verify_data_in_db_helper
    cnx = mysql_connect("test_cab")
TypeError: mysql_connect() takes exactly 2 arguments (1 given)
]]>		</error>
	</testcase>
	<testcase classname="test_segment_size_post_production_tests.ProductionTests" name="test_users_in_us_and_soccer_moms" time="1.441">
		<error message="mysql_connect() takes exactly 2 arguments (1 given)" type="TypeError">
<![CDATA[Traceback (most recent call last):
  File "/Users/sakthigurumaharaj/Desktop/xad/sakthixad/cab_automation/test_segment_size_post_production_tests.py", line 638, in test_users_in_us_and_soccer_moms
    verify_data_in_db_helper(count,"46",query)
  File "/Users/sakthigurumaharaj/Desktop/xad/sakthixad/cab_automation/framework/helpers/prod_data_validation_helper.py", line 21, in verify_data_in_db_helper
    cnx = mysql_connect("test_cab")
TypeError: mysql_connect() takes exactly 2 arguments (1 given)
]]>		</error>
	</testcase>
	<testcase classname="test_segment_size_post_production_tests.ProductionTests" name="test_users_in_us_and_sportsenthusiasts" time="2.558">
		<error message="mysql_connect() takes exactly 2 arguments (1 given)" type="TypeError">
<![CDATA[Traceback (most recent call last):
  File "/Users/sakthigurumaharaj/Desktop/xad/sakthixad/cab_automation/test_segment_size_post_production_tests.py", line 664, in test_users_in_us_and_sportsenthusiasts
    verify_data_in_db_helper(count,"48",query)
  File "/Users/sakthigurumaharaj/Desktop/xad/sakthixad/cab_automation/framework/helpers/prod_data_validation_helper.py", line 21, in verify_data_in_db_helper
    cnx = mysql_connect("test_cab")
TypeError: mysql_connect() takes exactly 2 arguments (1 given)
]]>		</error>
	</testcase>
	<testcase classname="test_segment_size_post_production_tests.ProductionTests" name="test_users_in_us_and_stay_at_mom_and_are_female" time="2.350">
		<error message="mysql_connect() takes exactly 2 arguments (1 given)" type="TypeError">
<![CDATA[Traceback (most recent call last):
  File "/Users/sakthigurumaharaj/Desktop/xad/sakthixad/cab_automation/test_segment_size_post_production_tests.py", line 1542, in test_users_in_us_and_stay_at_mom_and_are_female
    verify_data_in_db_helper(count,"83",query)
  File "/Users/sakthigurumaharaj/Desktop/xad/sakthixad/cab_automation/framework/helpers/prod_data_validation_helper.py", line 21, in verify_data_in_db_helper
    cnx = mysql_connect("test_cab")
TypeError: mysql_connect() takes exactly 2 arguments (1 given)
]]>		</error>
	</testcase>
	<testcase classname="test_segment_size_post_production_tests.ProductionTests" name="test_users_in_us_and_unknown" time="2.460">
		<error message="mysql_connect() takes exactly 2 arguments (1 given)" type="TypeError">
<![CDATA[Traceback (most recent call last):
  File "/Users/sakthigurumaharaj/Desktop/xad/sakthixad/cab_automation/test_segment_size_post_production_tests.py", line 77, in test_users_in_us_and_unknown
    verify_data_in_db_helper(count,"5",query)
  File "/Users/sakthigurumaharaj/Desktop/xad/sakthixad/cab_automation/framework/helpers/prod_data_validation_helper.py", line 21, in verify_data_in_db_helper
    cnx = mysql_connect("test_cab")
TypeError: mysql_connect() takes exactly 2 arguments (1 given)
]]>		</error>
	</testcase>
	<testcase classname="test_segment_size_post_production_tests.ProductionTests" name="test_users_in_us_and_unknown_age" time="1.668">
		<error message="mysql_connect() takes exactly 2 arguments (1 given)" type="TypeError">
<![CDATA[Traceback (most recent call last):
  File "/Users/sakthigurumaharaj/Desktop/xad/sakthixad/cab_automation/test_segment_size_post_production_tests.py", line 228, in test_users_in_us_and_unknown_age
    verify_data_in_db_helper(count,"16",query)
  File "/Users/sakthigurumaharaj/Desktop/xad/sakthixad/cab_automation/framework/helpers/prod_data_validation_helper.py", line 21, in verify_data_in_db_helper
    cnx = mysql_connect("test_cab")
TypeError: mysql_connect() takes exactly 2 arguments (1 given)
]]>		</error>
	</testcase>
	<testcase classname="test_segment_size_post_production_tests.ProductionTests" name="test_users_in_us_and_visited_home_depot" time="1.404">
		<error message="mysql_connect() takes exactly 2 arguments (1 given)" type="TypeError">
<![CDATA[Traceback (most recent call last):
  File "/Users/sakthigurumaharaj/Desktop/xad/sakthixad/cab_automation/test_segment_size_post_production_tests.py", line 381, in test_users_in_us_and_visited_home_depot
    verify_data_in_db_helper(count,"27",query)
  File "/Users/sakthigurumaharaj/Desktop/xad/sakthixad/cab_automation/framework/helpers/prod_data_validation_helper.py", line 21, in verify_data_in_db_helper
    cnx = mysql_connect("test_cab")
TypeError: mysql_connect() takes exactly 2 arguments (1 given)
]]>		</error>
	</testcase>
	<testcase classname="test_segment_size_post_production_tests.ProductionTests" name="test_users_in_us_and_visited_kfc" time="2.248">
		<error message="mysql_connect() takes exactly 2 arguments (1 given)" type="TypeError">
<![CDATA[Traceback (most recent call last):
  File "/Users/sakthigurumaharaj/Desktop/xad/sakthixad/cab_automation/test_segment_size_post_production_tests.py", line 355, in test_users_in_us_and_visited_kfc
    verify_data_in_db_helper(count,"25",query)
  File "/Users/sakthigurumaharaj/Desktop/xad/sakthixad/cab_automation/framework/helpers/prod_data_validation_helper.py", line 21, in verify_data_in_db_helper
    cnx = mysql_connect("test_cab")
TypeError: mysql_connect() takes exactly 2 arguments (1 given)
]]>		</error>
	</testcase>
	<testcase classname="test_segment_size_post_production_tests.ProductionTests" name="test_users_in_us_and_visited_mcdonalds" time="1.637">
		<error message="mysql_connect() takes exactly 2 arguments (1 given)" type="TypeError">
<![CDATA[Traceback (most recent call last):
  File "/Users/sakthigurumaharaj/Desktop/xad/sakthixad/cab_automation/test_segment_size_post_production_tests.py", line 420, in test_users_in_us_and_visited_mcdonalds
    verify_data_in_db_helper(count,"30",query)
  File "/Users/sakthigurumaharaj/Desktop/xad/sakthixad/cab_automation/framework/helpers/prod_data_validation_helper.py", line 21, in verify_data_in_db_helper
    cnx = mysql_connect("test_cab")
TypeError: mysql_connect() takes exactly 2 arguments (1 given)
]]>		</error>
	</testcase>
	<testcase classname="test_segment_size_post_production_tests.ProductionTests" name="test_users_in_us_and_visited_taco_bell" time="2.258">
		<error message="mysql_connect() takes exactly 2 arguments (1 given)" type="TypeError">
<![CDATA[Traceback (most recent call last):
  File "/Users/sakthigurumaharaj/Desktop/xad/sakthixad/cab_automation/test_segment_size_post_production_tests.py", line 433, in test_users_in_us_and_visited_taco_bell
    verify_data_in_db_helper(count,"31",query)
  File "/Users/sakthigurumaharaj/Desktop/xad/sakthixad/cab_automation/framework/helpers/prod_data_validation_helper.py", line 21, in verify_data_in_db_helper
    cnx = mysql_connect("test_cab")
TypeError: mysql_connect() takes exactly 2 arguments (1 given)
]]>		</error>
	</testcase>
	<testcase classname="test_segment_size_post_production_tests.ProductionTests" name="test_users_in_us_and_visited_walmart_supercenter" time="2.528">
		<error message="mysql_connect() takes exactly 2 arguments (1 given)" type="TypeError">
<![CDATA[Traceback (most recent call last):
  File "/Users/sakthigurumaharaj/Desktop/xad/sakthixad/cab_automation/test_segment_size_post_production_tests.py", line 394, in test_users_in_us_and_visited_walmart_supercenter
    verify_data_in_db_helper(count,"28",query)
  File "/Users/sakthigurumaharaj/Desktop/xad/sakthixad/cab_automation/framework/helpers/prod_data_validation_helper.py", line 21, in verify_data_in_db_helper
    cnx = mysql_connect("test_cab")
TypeError: mysql_connect() takes exactly 2 arguments (1 given)
]]>		</error>
	</testcase>
	<testcase classname="test_segment_size_post_production_tests.ProductionTests" name="test_users_in_usa_and_business_travellers_and_not_visited_kfc" time="2.176">
		<error message="mysql_connect() takes exactly 2 arguments (1 given)" type="TypeError">
<![CDATA[Traceback (most recent call last):
  File "/Users/sakthigurumaharaj/Desktop/xad/sakthixad/cab_automation/test_segment_size_post_production_tests.py", line 931, in test_users_in_usa_and_business_travellers_and_not_visited_kfc
    verify_data_in_db_helper(count,"68",query)
  File "/Users/sakthigurumaharaj/Desktop/xad/sakthixad/cab_automation/framework/helpers/prod_data_validation_helper.py", line 21, in verify_data_in_db_helper
    cnx = mysql_connect("test_cab")
TypeError: mysql_connect() takes exactly 2 arguments (1 given)
]]>		</error>
	</testcase>
	<testcase classname="test_segment_size_post_production_tests.ProductionTests" name="test_users_in_usa_and_business_travellers_and_visited_kfc" time="1.434">
		<error message="mysql_connect() takes exactly 2 arguments (1 given)" type="TypeError">
<![CDATA[Traceback (most recent call last):
  File "/Users/sakthigurumaharaj/Desktop/xad/sakthixad/cab_automation/test_segment_size_post_production_tests.py", line 918, in test_users_in_usa_and_business_travellers_and_visited_kfc
    verify_data_in_db_helper(count,"67",query)
  File "/Users/sakthigurumaharaj/Desktop/xad/sakthixad/cab_automation/framework/helpers/prod_data_validation_helper.py", line 21, in verify_data_in_db_helper
    cnx = mysql_connect("test_cab")
TypeError: mysql_connect() takes exactly 2 arguments (1 given)
]]>		</error>
	</testcase>
	<testcase classname="test_segment_size_post_production_tests.ProductionTests" name="test_users_in_usa_and_category_automobile_dealers_new_cars" time="2.450">
		<error message="mysql_connect() takes exactly 2 arguments (1 given)" type="TypeError">
<![CDATA[Traceback (most recent call last):
  File "/Users/sakthigurumaharaj/Desktop/xad/sakthixad/cab_automation/test_segment_size_post_production_tests.py", line 472, in test_users_in_usa_and_category_automobile_dealers_new_cars
    verify_data_in_db_helper(count,"34",query)
  File "/Users/sakthigurumaharaj/Desktop/xad/sakthixad/cab_automation/framework/helpers/prod_data_validation_helper.py", line 21, in verify_data_in_db_helper
    cnx = mysql_connect("test_cab")
TypeError: mysql_connect() takes exactly 2 arguments (1 given)
]]>		</error>
	</testcase>
	<testcase classname="test_segment_size_post_production_tests.ProductionTests" name="test_users_in_usa_and_category_department_stores" time="2.262">
		<error message="mysql_connect() takes exactly 2 arguments (1 given)" type="TypeError">
<![CDATA[Traceback (most recent call last):
  File "/Users/sakthigurumaharaj/Desktop/xad/sakthixad/cab_automation/test_segment_size_post_production_tests.py", line 498, in test_users_in_usa_and_category_department_stores
    verify_data_in_db_helper(count,"36",query)
  File "/Users/sakthigurumaharaj/Desktop/xad/sakthixad/cab_automation/framework/helpers/prod_data_validation_helper.py", line 21, in verify_data_in_db_helper
    cnx = mysql_connect("test_cab")
TypeError: mysql_connect() takes exactly 2 arguments (1 given)
]]>		</error>
	</testcase>
	<testcase classname="test_segment_size_post_production_tests.ProductionTests" name="test_users_in_usa_and_category_pharmacies" time="2.450">
		<error message="mysql_connect() takes exactly 2 arguments (1 given)" type="TypeError">
<![CDATA[Traceback (most recent call last):
  File "/Users/sakthigurumaharaj/Desktop/xad/sakthixad/cab_automation/test_segment_size_post_production_tests.py", line 511, in test_users_in_usa_and_category_pharmacies
    verify_data_in_db_helper(count,"37",query)
  File "/Users/sakthigurumaharaj/Desktop/xad/sakthixad/cab_automation/framework/helpers/prod_data_validation_helper.py", line 21, in verify_data_in_db_helper
    cnx = mysql_connect("test_cab")
TypeError: mysql_connect() takes exactly 2 arguments (1 given)
]]>		</error>
	</testcase>
	<testcase classname="test_segment_size_post_production_tests.ProductionTests" name="test_users_in_usa_and_category_restaurants" time="1.848">
		<error message="mysql_connect() takes exactly 2 arguments (1 given)" type="TypeError">
<![CDATA[Traceback (most recent call last):
  File "/Users/sakthigurumaharaj/Desktop/xad/sakthixad/cab_automation/test_segment_size_post_production_tests.py", line 485, in test_users_in_usa_and_category_restaurants
    verify_data_in_db_helper(count,"35",query)
  File "/Users/sakthigurumaharaj/Desktop/xad/sakthixad/cab_automation/framework/helpers/prod_data_validation_helper.py", line 21, in verify_data_in_db_helper
    cnx = mysql_connect("test_cab")
TypeError: mysql_connect() takes exactly 2 arguments (1 given)
]]>		</error>
	</testcase>
	<testcase classname="test_segment_size_post_production_tests.ProductionTests" name="test_users_in_usa_and_soccer_moms_and_dad" time="2.251">
		<error message="mysql_connect() takes exactly 2 arguments (1 given)" type="TypeError">
<![CDATA[Traceback (most recent call last):
  File "/Users/sakthigurumaharaj/Desktop/xad/sakthixad/cab_automation/test_segment_size_post_production_tests.py", line 811, in test_users_in_usa_and_soccer_moms_and_dad
    verify_data_in_db_helper(count,"59",query)
  File "/Users/sakthigurumaharaj/Desktop/xad/sakthixad/cab_automation/framework/helpers/prod_data_validation_helper.py", line 21, in verify_data_in_db_helper
    cnx = mysql_connect("test_cab")
TypeError: mysql_connect() takes exactly 2 arguments (1 given)
]]>		</error>
	</testcase>
	<testcase classname="test_segment_size_post_production_tests.ProductionTests" name="test_users_in_usa_and_soccer_moms_and_gender_female" time="2.365">
		<error message="mysql_connect() takes exactly 2 arguments (1 given)" type="TypeError">
<![CDATA[Traceback (most recent call last):
  File "/Users/sakthigurumaharaj/Desktop/xad/sakthixad/cab_automation/test_segment_size_post_production_tests.py", line 784, in test_users_in_usa_and_soccer_moms_and_gender_female
    verify_data_in_db_helper(count,"57",query)
  File "/Users/sakthigurumaharaj/Desktop/xad/sakthixad/cab_automation/framework/helpers/prod_data_validation_helper.py", line 21, in verify_data_in_db_helper
    cnx = mysql_connect("test_cab")
TypeError: mysql_connect() takes exactly 2 arguments (1 given)
]]>		</error>
	</testcase>
	<testcase classname="test_segment_size_post_production_tests.ProductionTests" name="test_users_in_usa_and_soccer_moms_and_gender_male" time="1.388">
		<error message="mysql_connect() takes exactly 2 arguments (1 given)" type="TypeError">
<![CDATA[Traceback (most recent call last):
  File "/Users/sakthigurumaharaj/Desktop/xad/sakthixad/cab_automation/test_segment_size_post_production_tests.py", line 798, in test_users_in_usa_and_soccer_moms_and_gender_male
    verify_data_in_db_helper(count,"58",query)
  File "/Users/sakthigurumaharaj/Desktop/xad/sakthixad/cab_automation/framework/helpers/prod_data_validation_helper.py", line 21, in verify_data_in_db_helper
    cnx = mysql_connect("test_cab")
TypeError: mysql_connect() takes exactly 2 arguments (1 given)
]]>		</error>
	</testcase>
	<testcase classname="test_segment_size_post_production_tests.ProductionTests" name="test_users_in_usa_and_soccer_moms_and_visted_target" time="2.397">
		<error message="mysql_connect() takes exactly 2 arguments (1 given)" type="TypeError">
<![CDATA[Traceback (most recent call last):
  File "/Users/sakthigurumaharaj/Desktop/xad/sakthixad/cab_automation/test_segment_size_post_production_tests.py", line 944, in test_users_in_usa_and_soccer_moms_and_visted_target
    verify_data_in_db_helper(count,"69",query)
  File "/Users/sakthigurumaharaj/Desktop/xad/sakthixad/cab_automation/framework/helpers/prod_data_validation_helper.py", line 21, in verify_data_in_db_helper
    cnx = mysql_connect("test_cab")
TypeError: mysql_connect() takes exactly 2 arguments (1 given)
]]>		</error>
	</testcase>
	<testcase classname="test_segment_size_post_production_tests.ProductionTests" name="test_users_in_usa_and_soccermoms_not_visited_target" time="2.596">
		<error message="mysql_connect() takes exactly 2 arguments (1 given)" type="TypeError">
<![CDATA[Traceback (most recent call last):
  File "/Users/sakthigurumaharaj/Desktop/xad/sakthixad/cab_automation/test_segment_size_post_production_tests.py", line 996, in test_users_in_usa_and_soccermoms_not_visited_target
    verify_data_in_db_helper(count,"71",query)
  File "/Users/sakthigurumaharaj/Desktop/xad/sakthixad/cab_automation/framework/helpers/prod_data_validation_helper.py", line 21, in verify_data_in_db_helper
    cnx = mysql_connect("test_cab")
TypeError: mysql_connect() takes exactly 2 arguments (1 given)
]]>		</error>
	</testcase>
	<testcase classname="test_segment_size_post_production_tests.ProductionTests" name="test_users_in_usa_and_soccermoms_or_visited_target" time="2.935">
		<error message="mysql_connect() takes exactly 2 arguments (1 given)" type="TypeError">
<![CDATA[Traceback (most recent call last):
  File "/Users/sakthigurumaharaj/Desktop/xad/sakthixad/cab_automation/test_segment_size_post_production_tests.py", line 971, in test_users_in_usa_and_soccermoms_or_visited_target
    verify_data_in_db_helper(count,"70",query)
  File "/Users/sakthigurumaharaj/Desktop/xad/sakthixad/cab_automation/framework/helpers/prod_data_validation_helper.py", line 21, in verify_data_in_db_helper
    cnx = mysql_connect("test_cab")
TypeError: mysql_connect() takes exactly 2 arguments (1 given)
]]>		</error>
	</testcase>
	<testcase classname="test_segment_size_post_production_tests.ProductionTests" name="test_users_in_usa_and_visited_burger_king" time="1.428">
		<error message="mysql_connect() takes exactly 2 arguments (1 given)" type="TypeError">
<![CDATA[Traceback (most recent call last):
  File "/Users/sakthigurumaharaj/Desktop/xad/sakthixad/cab_automation/test_segment_size_post_production_tests.py", line 368, in test_users_in_usa_and_visited_burger_king
    verify_data_in_db_helper(count,"26",query)
  File "/Users/sakthigurumaharaj/Desktop/xad/sakthixad/cab_automation/framework/helpers/prod_data_validation_helper.py", line 21, in verify_data_in_db_helper
    cnx = mysql_connect("test_cab")
TypeError: mysql_connect() takes exactly 2 arguments (1 given)
]]>		</error>
	</testcase>
	<testcase classname="test_segment_size_post_production_tests.ProductionTests" name="test_users_in_usa_and_visited_costco" time="2.187">
		<error message="mysql_connect() takes exactly 2 arguments (1 given)" type="TypeError">
<![CDATA[Traceback (most recent call last):
  File "/Users/sakthigurumaharaj/Desktop/xad/sakthixad/cab_automation/test_segment_size_post_production_tests.py", line 446, in test_users_in_usa_and_visited_costco
    verify_data_in_db_helper(count,"32",query)
  File "/Users/sakthigurumaharaj/Desktop/xad/sakthixad/cab_automation/framework/helpers/prod_data_validation_helper.py", line 21, in verify_data_in_db_helper
    cnx = mysql_connect("test_cab")
TypeError: mysql_connect() takes exactly 2 arguments (1 given)
]]>		</error>
	</testcase>
	<testcase classname="test_segment_size_post_production_tests.ProductionTests" name="test_users_in_usa_and_visited_costco_and_target" time="2.457">
		<error message="mysql_connect() takes exactly 2 arguments (1 given)" type="TypeError">
<![CDATA[Traceback (most recent call last):
  File "/Users/sakthigurumaharaj/Desktop/xad/sakthixad/cab_automation/test_segment_size_post_production_tests.py", line 852, in test_users_in_usa_and_visited_costco_and_target
    verify_data_in_db_helper(count,"62",query)
  File "/Users/sakthigurumaharaj/Desktop/xad/sakthixad/cab_automation/framework/helpers/prod_data_validation_helper.py", line 21, in verify_data_in_db_helper
    cnx = mysql_connect("test_cab")
TypeError: mysql_connect() takes exactly 2 arguments (1 given)
]]>		</error>
	</testcase>
	<testcase classname="test_segment_size_post_production_tests.ProductionTests" name="test_users_in_usa_and_visited_home_depot_and_gender_female" time="1.783">
		<error message="mysql_connect() takes exactly 2 arguments (1 given)" type="TypeError">
<![CDATA[Traceback (most recent call last):
  File "/Users/sakthigurumaharaj/Desktop/xad/sakthixad/cab_automation/test_segment_size_post_production_tests.py", line 839, in test_users_in_usa_and_visited_home_depot_and_gender_female
    verify_data_in_db_helper(count,"61",query)
  File "/Users/sakthigurumaharaj/Desktop/xad/sakthixad/cab_automation/framework/helpers/prod_data_validation_helper.py", line 21, in verify_data_in_db_helper
    cnx = mysql_connect("test_cab")
TypeError: mysql_connect() takes exactly 2 arguments (1 given)
]]>		</error>
	</testcase>
	<testcase classname="test_segment_size_post_production_tests.ProductionTests" name="test_users_in_usa_and_visited_home_depot_and_gender_male" time="2.487">
		<error message="mysql_connect() takes exactly 2 arguments (1 given)" type="TypeError">
<![CDATA[Traceback (most recent call last):
  File "/Users/sakthigurumaharaj/Desktop/xad/sakthixad/cab_automation/test_segment_size_post_production_tests.py", line 825, in test_users_in_usa_and_visited_home_depot_and_gender_male
    verify_data_in_db_helper(count,"60",query)
  File "/Users/sakthigurumaharaj/Desktop/xad/sakthixad/cab_automation/framework/helpers/prod_data_validation_helper.py", line 21, in verify_data_in_db_helper
    cnx = mysql_connect("test_cab")
TypeError: mysql_connect() takes exactly 2 arguments (1 given)
]]>		</error>
	</testcase>
	<testcase classname="test_segment_size_post_production_tests.ProductionTests" name="test_users_in_usa_and_visited_kfc_and_taco" time="1.736">
		<error message="mysql_connect() takes exactly 2 arguments (1 given)" type="TypeError">
<![CDATA[Traceback (most recent call last):
  File "/Users/sakthigurumaharaj/Desktop/xad/sakthixad/cab_automation/test_segment_size_post_production_tests.py", line 892, in test_users_in_usa_and_visited_kfc_and_taco
    verify_data_in_db_helper(count,"65",query)
  File "/Users/sakthigurumaharaj/Desktop/xad/sakthixad/cab_automation/framework/helpers/prod_data_validation_helper.py", line 21, in verify_data_in_db_helper
    cnx = mysql_connect("test_cab")
TypeError: mysql_connect() takes exactly 2 arguments (1 given)
]]>		</error>
	</testcase>
	<testcase classname="test_segment_size_post_production_tests.ProductionTests" name="test_users_in_usa_and_visited_kfc_and_taco_and_mcdonalds" time="1.570">
		<error message="mysql_connect() takes exactly 2 arguments (1 given)" type="TypeError">
<![CDATA[Traceback (most recent call last):
  File "/Users/sakthigurumaharaj/Desktop/xad/sakthixad/cab_automation/test_segment_size_post_production_tests.py", line 879, in test_users_in_usa_and_visited_kfc_and_taco_and_mcdonalds
    verify_data_in_db_helper(count,"64",query)
  File "/Users/sakthigurumaharaj/Desktop/xad/sakthixad/cab_automation/framework/helpers/prod_data_validation_helper.py", line 21, in verify_data_in_db_helper
    cnx = mysql_connect("test_cab")
TypeError: mysql_connect() takes exactly 2 arguments (1 given)
]]>		</error>
	</testcase>
	<testcase classname="test_segment_size_post_production_tests.ProductionTests" name="test_users_in_usa_and_visited_kfc_or_taco" time="2.525">
		<error message="mysql_connect() takes exactly 2 arguments (1 given)" type="TypeError">
<![CDATA[Traceback (most recent call last):
  File "/Users/sakthigurumaharaj/Desktop/xad/sakthixad/cab_automation/test_segment_size_post_production_tests.py", line 905, in test_users_in_usa_and_visited_kfc_or_taco
    verify_data_in_db_helper(count,"66",query)
  File "/Users/sakthigurumaharaj/Desktop/xad/sakthixad/cab_automation/framework/helpers/prod_data_validation_helper.py", line 21, in verify_data_in_db_helper
    cnx = mysql_connect("test_cab")
TypeError: mysql_connect() takes exactly 2 arguments (1 given)
]]>		</error>
	</testcase>
	<testcase classname="test_segment_size_post_production_tests.ProductionTests" name="test_users_in_usa_and_visited_target" time="2.253">
		<error message="mysql_connect() takes exactly 2 arguments (1 given)" type="TypeError">
<![CDATA[Traceback (most recent call last):
  File "/Users/sakthigurumaharaj/Desktop/xad/sakthixad/cab_automation/test_segment_size_post_production_tests.py", line 407, in test_users_in_usa_and_visited_target
    verify_data_in_db_helper(count,"29",query)
  File "/Users/sakthigurumaharaj/Desktop/xad/sakthixad/cab_automation/framework/helpers/prod_data_validation_helper.py", line 21, in verify_data_in_db_helper
    cnx = mysql_connect("test_cab")
TypeError: mysql_connect() takes exactly 2 arguments (1 given)
]]>		</error>
	</testcase>
	<testcase classname="test_segment_size_post_production_tests.ProductionTests" name="test_users_in_usa_and_visited_target_and_visited_departmental_stores" time="2.660">
		<error message="mysql_connect() takes exactly 2 arguments (1 given)" type="TypeError">
<![CDATA[Traceback (most recent call last):
  File "/Users/sakthigurumaharaj/Desktop/xad/sakthixad/cab_automation/test_segment_size_post_production_tests.py", line 866, in test_users_in_usa_and_visited_target_and_visited_departmental_stores
    verify_data_in_db_helper(count,"63",query)
  File "/Users/sakthigurumaharaj/Desktop/xad/sakthixad/cab_automation/framework/helpers/prod_data_validation_helper.py", line 21, in verify_data_in_db_helper
    cnx = mysql_connect("test_cab")
TypeError: mysql_connect() takes exactly 2 arguments (1 given)
]]>		</error>
	</testcase>
	<testcase classname="test_segment_size_post_production_tests.ProductionTests" name="test_users_in_usa_and_visited_walmart" time="1.843">
		<error message="mysql_connect() takes exactly 2 arguments (1 given)" type="TypeError">
<![CDATA[Traceback (most recent call last):
  File "/Users/sakthigurumaharaj/Desktop/xad/sakthixad/cab_automation/test_segment_size_post_production_tests.py", line 459, in test_users_in_usa_and_visited_walmart
    verify_data_in_db_helper(count,"33",query)
  File "/Users/sakthigurumaharaj/Desktop/xad/sakthixad/cab_automation/framework/helpers/prod_data_validation_helper.py", line 21, in verify_data_in_db_helper
    cnx = mysql_connect("test_cab")
TypeError: mysql_connect() takes exactly 2 arguments (1 given)
]]>		</error>
	</testcase>
	<testcase classname="test_segment_size_post_production_tests.ProductionTests" name="test_users_who_dont_have_country" time="5.531">
		<error message="mysql_connect() takes exactly 2 arguments (1 given)" type="TypeError">
<![CDATA[Traceback (most recent call last):
  File "/Users/sakthigurumaharaj/Desktop/xad/sakthixad/cab_automation/test_segment_size_post_production_tests.py", line 1566, in test_users_who_dont_have_country
    verify_data_in_db_helper(final_count,"84",query)
  File "/Users/sakthigurumaharaj/Desktop/xad/sakthixad/cab_automation/framework/helpers/prod_data_validation_helper.py", line 21, in verify_data_in_db_helper
    cnx = mysql_connect("test_cab")
TypeError: mysql_connect() takes exactly 2 arguments (1 given)
]]>		</error>
	</testcase>
	<system-out>
<![CDATA[]]>	</system-out>
	<system-err>
<![CDATA[]]>	</system-err>
</testsuite>
